<?xml version="1.0" encoding="UTF-8"?>
<testng-results skipped="0" failed="1" ignored="0" total="1" passed="0">
  <reporter-output>
  </reporter-output>
  <suite name="Default suite" duration-ms="352" started-at="2018-07-27T07:06:36Z" finished-at="2018-07-27T07:06:37Z">
    <groups>
    </groups>
    <test name="Default test" duration-ms="352" started-at="2018-07-27T07:06:36Z" finished-at="2018-07-27T07:06:37Z">
      <class name="com.NewMavenProject1.NewMavenProject1.Testcases.MysqlConnection">
        <test-method status="FAIL" signature="test()[pri:0, instance:com.NewMavenProject1.NewMavenProject1.Testcases.MysqlConnection@5bcea91b]" name="test" duration-ms="307" started-at="2018-07-27T07:06:36Z" finished-at="2018-07-27T07:06:37Z">
          <exception class="java.sql.SQLNonTransientConnectionException">
            <message>
              <![CDATA[CLIENT_PLUGIN_AUTH is required]]>
            </message>
            <full-stacktrace>
              <![CDATA[java.sql.SQLNonTransientConnectionException: CLIENT_PLUGIN_AUTH is required
at com.mysql.cj.jdbc.exceptions.SQLError.createSQLException(SQLError.java:108)
at com.mysql.cj.jdbc.exceptions.SQLError.createSQLException(SQLError.java:95)
at com.mysql.cj.jdbc.exceptions.SQLError.createSQLException(SQLError.java:87)
at com.mysql.cj.jdbc.exceptions.SQLError.createSQLException(SQLError.java:61)
at com.mysql.cj.jdbc.exceptions.SQLError.createSQLException(SQLError.java:71)
at com.mysql.cj.jdbc.exceptions.SQLExceptionsMapping.translateException(SQLExceptionsMapping.java:79)
at com.mysql.cj.jdbc.ConnectionImpl.createNewIO(ConnectionImpl.java:862)
at com.mysql.cj.jdbc.ConnectionImpl.<init>(ConnectionImpl.java:444)
at com.mysql.cj.jdbc.ConnectionImpl.getInstance(ConnectionImpl.java:230)
at com.mysql.cj.jdbc.NonRegisteringDriver.connect(NonRegisteringDriver.java:226)
at java.sql.DriverManager.getConnection(Unknown Source)
at java.sql.DriverManager.getConnection(Unknown Source)
at com.NewMavenProject1.NewMavenProject1.Testcases.MysqlConnection.test(MysqlConnection.java:15)
at sun.reflect.NativeMethodAccessorImpl.invoke0(Native Method)
at sun.reflect.NativeMethodAccessorImpl.invoke(Unknown Source)
at sun.reflect.DelegatingMethodAccessorImpl.invoke(Unknown Source)
at java.lang.reflect.Method.invoke(Unknown Source)
at org.testng.internal.MethodInvocationHelper.invokeMethod(MethodInvocationHelper.java:124)
at org.testng.internal.Invoker.invokeMethod(Invoker.java:580)
at org.testng.internal.Invoker.invokeTestMethod(Invoker.java:716)
at org.testng.internal.Invoker.invokeTestMethods(Invoker.java:988)
at org.testng.internal.TestMethodWorker.invokeTestMethods(TestMethodWorker.java:125)
at org.testng.internal.TestMethodWorker.run(TestMethodWorker.java:109)
at org.testng.TestRunner.privateRun(TestRunner.java:648)
at org.testng.TestRunner.run(TestRunner.java:505)
at org.testng.SuiteRunner.runTest(SuiteRunner.java:455)
at org.testng.SuiteRunner.runSequentially(SuiteRunner.java:450)
at org.testng.SuiteRunner.privateRun(SuiteRunner.java:415)
at org.testng.SuiteRunner.run(SuiteRunner.java:364)
at org.testng.SuiteRunnerWorker.runSuite(SuiteRunnerWorker.java:52)
at org.testng.SuiteRunnerWorker.run(SuiteRunnerWorker.java:84)
at org.testng.TestNG.runSuitesSequentially(TestNG.java:1208)
at org.testng.TestNG.runSuitesLocally(TestNG.java:1137)
at org.testng.TestNG.runSuites(TestNG.java:1049)
at org.testng.TestNG.run(TestNG.java:1017)
at org.testng.remote.AbstractRemoteTestNG.run(AbstractRemoteTestNG.java:114)
at org.testng.remote.RemoteTestNG.initAndRun(RemoteTestNG.java:251)
at org.testng.remote.RemoteTestNG.main(RemoteTestNG.java:77)
Caused by: com.mysql.cj.exceptions.UnableToConnectException: CLIENT_PLUGIN_AUTH is required
at sun.reflect.NativeConstructorAccessorImpl.newInstance0(Native Method)
at sun.reflect.NativeConstructorAccessorImpl.newInstance(Unknown Source)
at sun.reflect.DelegatingConstructorAccessorImpl.newInstance(Unknown Source)
at java.lang.reflect.Constructor.newInstance(Unknown Source)
at com.mysql.cj.exceptions.ExceptionFactory.createException(ExceptionFactory.java:59)
at com.mysql.cj.exceptions.ExceptionFactory.createException(ExceptionFactory.java:83)
at com.mysql.cj.protocol.a.NativeAuthenticationProvider.connect(NativeAuthenticationProvider.java:220)
at com.mysql.cj.protocol.a.NativeProtocol.connect(NativeProtocol.java:1411)
at com.mysql.cj.NativeSession.connect(NativeSession.java:165)
at com.mysql.cj.jdbc.ConnectionImpl.connectOneTryOnly(ConnectionImpl.java:982)
at com.mysql.cj.jdbc.ConnectionImpl.createNewIO(ConnectionImpl.java:852)
... 31 more
]]>
            </full-stacktrace>
          </exception> <!-- java.sql.SQLNonTransientConnectionException -->
          <reporter-output>
          </reporter-output>
        </test-method> <!-- test -->
      </class> <!-- com.NewMavenProject1.NewMavenProject1.Testcases.MysqlConnection -->
    </test> <!-- Default test -->
  </suite> <!-- Default suite -->
</testng-results>
